Workbook

Sheet Project Information
B2: =INDEX(Translations!$D:$ZZ,MATCH(1001,Translations!$A:$A,0),MATCH($C$4,Translations!$D$1:$ZZ$1,0))
B4: =INDEX(Translations!$D:$ZZ,MATCH(1002,Translations!$A:$A,0),MATCH($C$4,Translations!$D$1:$ZZ$1,0)) | C4: TR
B6: =INDEX(Translations!$D:$ZZ,MATCH(1003,Translations!$A:$A,0),MATCH($C$4,Translations!$D$1:$ZZ$1,0)) | C6: Ufuk Enerji AŞ
B7: =INDEX(Translations!$D:$ZZ,MATCH(1004,Translations!$A:$A,0),MATCH($C$4,Translations!$D$1:$ZZ$1,0)) | C7: S4 Dönüşüm
B8: =INDEX(Translations!$D:$ZZ,MATCH(1005,Translations!$A:$A,0),MATCH($C$4,Translations!$D$1:$ZZ$1,0)) | C8: 46156.374
B10: =INDEX(Translations!$D:$ZZ,MATCH(1006,Translations!$A:$A,0),MATCH($C$4,Translations!$D$1:$ZZ$1,0)) | C10: Konfeksiyon
B11: =INDEX(Translations!$D:$ZZ,MATCH(1007,Translations!$A:$A,0),MATCH($C$4,Translations!$D$1:$ZZ$1,0)) | C11: Conversion
B12: =INDEX(Translations!$D:$ZZ,MATCH(1008,Translations!$A:$A,0),MATCH($C$4,Translations!$D$1:$ZZ$1,0)) | C12: SAP S/4HANA Private Cloud
B14: =INDEX(Translations!$D:$ZZ,MATCH(1009,Translations!$A:$A,0),MATCH($C$4,Translations!$D$1:$ZZ$1,0)) | C14: Ufuk Turcan
B15: =INDEX(Translations!$D:$ZZ,MATCH(1010,Translations!$A:$A,0),MATCH($C$4,Translations!$D$1:$ZZ$1,0)) | C15: V1
B17: =INDEX(Translations!$D:$ZZ,MATCH(1011,Translations!$A:$A,0),MATCH($C$4,Translations!$D$1:$ZZ$1,0)) | C17: Dikkat

Sheet Scope
A1: =INDEX(Translations!$D:$ZZ, MATCH(1,Translations!$A:$A,0), MATCH('Project Information'!$C$4,Translations!$D$1:$ZZ$1,0))
A4: =INDEX(Translations!$D:$ZZ, MATCH(4,Translations!$A:$A,0), MATCH('Project Information'!$C$4,Translations!$D$1:$ZZ$1,0))
A5: =INDEX(Translations!$D:$ZZ, MATCH(5,Translations!$A:$A,0), MATCH('Project Information'!$C$4,Translations!$D$1:$ZZ$1,0)) | B5: =INDEX(Translations!$D:$ZZ, MATCH(6,Translations!$A:$A,0), MATCH('Project Information'!$C$4,Translations!$D$1:$ZZ$1,0))
A6: =INDEX(Translations!$D:$ZZ, MATCH(7,Translations!$A:$A,0), MATCH('Project Information'!$C$4,Translations!$D$1:$ZZ$1,0)) | B6: =INDEX(Translations!$D:$ZZ, MATCH(8,Translations!$A:$A,0), MATCH('Project Information'!$C$4,Translations!$D$1:$ZZ$1,0))
A7: =INDEX(Translations!$D:$ZZ, MATCH(9,Translations!$A:$A,0), MATCH('Project Information'!$C$4,Translations!$D$1:$ZZ$1,0)) | B7: =INDEX(Translations!$D:$ZZ, MATCH(10,Translations!$A:$A,0), MATCH('Project Information'!$C$4,Translations!$D$1:$ZZ$1,0))
A8: =INDEX(Translations!$D:$ZZ, MATCH(11,Translations!$A:$A,0), MATCH('Project Information'!$C$4,Translations!$D$1:$ZZ$1,0)) | B8: =INDEX(Translations!$D:$ZZ, MATCH(12,Translations!$A:$A,0), MATCH('Project Information'!$C$4,Translations!$D$1:$ZZ$1,0))
A9: =INDEX(Translations!$D:$ZZ, MATCH(13,Translations!$A:$A,0), MATCH('Project Information'!$C$4,Translations!$D$1:$ZZ$1,0)) | B9: =SUM($H$13:$H$59) | J9: =IF($B$9<=40,"S",IF($B$9<=70,"M",IF($B$9<=100,"L","XL")))
A10: =INDEX(Translations!$D:$ZZ, MATCH(14,Translations!$A:$A,0), MATCH('Project Information'!$C$4,Translations!$D$1:$ZZ$1,0)) | B10: =IF($J$9="S",INDEX(Translations!$D:$ZZ,MATCH(5,Translations!$A:$A,0),MATCH('Project Information'!$C$4,Translations!$D$1:$ZZ$1,0)),IF($J$9="M",INDEX(Translations!$D:$ZZ,MATCH(7,Translations!$A:$A,0),MATCH('Project Information'!$C$4,Translations!$D$1:$ZZ$1,0)),IF($J$9="L",INDEX(Translations!$D:$ZZ,MATCH(9,Translations!$A:$A,0),MATCH('Project Information'!$C$4,Translations!$D$1:$ZZ$1,0)),INDEX(Translations!$D:$ZZ,MATCH(11,Translations!$A:$A,0),MATCH('Project Information'!$C$4,Translations!$D$1:$ZZ$1,0)))))
A11: =INDEX(Translations!$D:$ZZ, MATCH(15,Translations!$A:$A,0), MATCH('Project Information'!$C$4,Translations!$D$1:$ZZ$1,0))
A12: =INDEX(Translations!$D:$ZZ, MATCH(16,Translations!$A:$A,0), MATCH('Project Information'!$C$4,Translations!$D$1:$ZZ$1,0)) | B12: =INDEX(Translations!$D:$ZZ, MATCH(17,Translations!$A:$A,0), MATCH('Project Information'!$C$4,Translations!$D$1:$ZZ$1,0)) | C12: =INDEX(Translations!$D:$ZZ, MATCH(18,Translations!$A:$A,0), MATCH('Project Information'!$C$4,Translations!$D$1:$ZZ$1,0)) | D12: =INDEX(Translations!$D:$ZZ, MATCH(19,Translations!$A:$A,0), MATCH('Project Information'!$C$4,Translations!$D$1:$ZZ$1,0)) | E12: =INDEX(Translations!$D:$ZZ, MATCH(20,Translations!$A:$A,0), MATCH('Project Information'!$C$4,Translations!$D$1:$ZZ$1,0)) | F12: =INDEX(Translations!$D:$ZZ, MATCH(21,Translations!$A:$A,0), MATCH('Project Information'!$C$4,Translations!$D$1:$ZZ$1,0)) | G12: =INDEX(Translations!$D:$ZZ, MATCH(22,Translations!$A:$A,0), MATCH('Project Information'!$C$4,Translations!$D$1:$ZZ$1,0)) | H12: =INDEX(Translations!$D:$ZZ, MATCH(23,Translations!$A:$A,0), MATCH('Project Information'!$C$4,Translations!$D$1:$ZZ$1,0)) | I12: =INDEX(Translations!$D:$ZZ, MATCH(24,Translations!$A:$A,0), MATCH('Project Information'!$C$4,Translations!$D$1:$ZZ$1,0)) | K12: Applicable?
A13: 1 | B13: =INDEX(Translations!$D:$ZZ, MATCH(25,Translations!$A:$A,0), MATCH('Project Information'!$C$4,Translations!$D$1:$ZZ$1,0)) | C13: =INDEX(Translations!$D:$ZZ, MATCH(26,Translations!$A:$A,0), MATCH('Project Information'!$C$4,Translations!$D$1:$ZZ$1,0)) | D13: =INDEX(Translations!$D:$ZZ, MATCH(27,Translations!$A:$A,0), MATCH('Project Information'!$C$4,Translations!$D$1:$ZZ$1,0)) | E13: 5 | G13: 2 | H13: =IF(OR(TRIM(F13)="Evet",TRIM(F13)="Yes"),E13,IF(G13="","",E13*G13)) | K13: =IFERROR(AND(OR(INDEX('Question Restrictions'!$D:$D,MATCH($B13,'Question Restrictions'!$C:$C,0))="All",ISNUMBER(SEARCH('Project Information'!$C$10,INDEX('Question Restrictions'!$D:$D,MATCH($B13,'Question Restrictions'!$C:$C,0))))),OR(INDEX('Question Restrictions'!$E:$E,MATCH($B13,'Question Restrictions'!$C:$C,0))="All",ISNUMBER(SEARCH('Project Information'!$C$11,INDEX('Question Restrictions'!$E:$E,MATCH($B13,'Question Restrictions'!$C:$C,0))))),OR(INDEX('Question Restrictions'!$F:$F,MATCH($B13,'Question Restrictions'!$C:$C,0))="All",ISNUMBER(SEARCH('Project Information'!$C$12,INDEX('Question Restrictions'!$F:$F,MATCH($B13,'Question Restrictions'!$C:$C,0))))),INDEX('Question Restrictions'!$G:$G,MATCH($B13,'Question Restrictions'!$C:$C,0))="Yes"),TRUE())
A14: 2 | B14: =INDEX(Translations!$D:$ZZ, MATCH(164,Translations!$A:$A,0), MATCH('Project Information'!$C$4,Translations!$D$1:$ZZ$1,0)) | C14: =INDEX(Translations!$D:$ZZ, MATCH(165,Translations!$A:$A,0), MATCH('Project Information'!$C$4,Translations!$D$1:$ZZ$1,0)) | D14: =INDEX(Translations!$D:$ZZ, MATCH(27,Translations!$A:$A,0), MATCH('Project Information'!$C$4,Translations!$D$1:$ZZ$1,0)) | H14: =IF(OR(TRIM(F14)="Evet",TRIM(F14)="Yes"),E14,IF(G14="","",E14*G14)) | K14: =IFERROR(AND(OR(INDEX('Question Restrictions'!$D:$D,MATCH($B14,'Question Restrictions'!$C:$C,0))="All",ISNUMBER(SEARCH('Project Information'!$C$10,INDEX('Question Restrictions'!$D:$D,MATCH($B14,'Question Restrictions'!$C:$C,0))))),OR(INDEX('Question Restrictions'!$E:$E,MATCH($B14,'Question Restrictions'!$C:$C,0))="All",ISNUMBER(SEARCH('Project Information'!$C$11,INDEX('Question Restrictions'!$E:$E,MATCH($B14,'Question Restrictions'!$C:$C,0))))),OR(INDEX('Question Restrictions'!$F:$F,MATCH($B14,'Question Restrictions'!$C:$C,0))="All",ISNUMBER(SEARCH('Project Information'!$C$12,INDEX('Question Restrictions'!$F:$F,MATCH($B14,'Question Restrictions'!$C:$C,0))))),INDEX('Question Restrictions'!$G:$G,MATCH($B14,'Question Restrictions'!$C:$C,0))="Yes"),TRUE())
A15: 3 | B15: =INDEX(Translations!$D:$ZZ, MATCH(30,Translations!$A:$A,0), MATCH('Project Information'!$C$4,Translations!$D$1:$ZZ$1,0)) | C15: =INDEX(Translations!$D:$ZZ, MATCH(31,Translations!$A:$A,0), MATCH('Project Information'!$C$4,Translations!$D$1:$ZZ$1,0)) | D15: =INDEX(Translations!$D:$ZZ, MATCH(27,Translations!$A:$A,0), MATCH('Project Information'!$C$4,Translations!$D$1:$ZZ$1,0)) | E15: 5 | H15: =IF(OR(TRIM(F15)="Evet",TRIM(F15)="Yes"),E15,IF(G15="","",E15*G15)) | K15: =IFERROR(AND(OR(INDEX('Question Restrictions'!$D:$D,MATCH($B15,'Question Restrictions'!$C:$C,0))="All",ISNUMBER(SEARCH('Project Information'!$C$10,INDEX('Question Restrictions'!$D:$D,MATCH($B15,'Question Restrictions'!$C:$C,0))))),OR(INDEX('Question Restrictions'!$E:$E,MATCH($B15,'Question Restrictions'!$C:$C,0))="All",ISNUMBER(SEARCH('Project Information'!$C$11,INDEX('Question Restrictions'!$E:$E,MATCH($B15,'Question Restrictions'!$C:$C,0))))),OR(INDEX('Question Restrictions'!$F:$F,MATCH($B15,'Question Restrictions'!$C:$C,0))="All",ISNUMBER(SEARCH('Project Information'!$C$12,INDEX('Question Restrictions'!$F:$F,MATCH($B15,'Question Restrictions'!$C:$C,0))))),INDEX('Question Restrictions'!$G:$G,MATCH($B15,'Question Restrictions'!$C:$C,0))="Yes"),TRUE())
A16: 4 | B16: =INDEX(Translations!$D:$ZZ, MATCH(167,Translations!$A:$A,0), MATCH('Project Information'!$C$4,Translations!$D$1:$ZZ$1,0)) | C16: =INDEX(Translations!$D:$ZZ, MATCH(168,Translations!$A:$A,0), MATCH('Project Information'!$C$4,Translations!$D$1:$ZZ$1,0)) | D16: =INDEX(Translations!$D:$ZZ, MATCH(27,Translations!$A:$A,0), MATCH('Project Information'!$C$4,Translations!$D$1:$ZZ$1,0)) | H16: =IF(OR(TRIM(F16)="Evet",TRIM(F16)="Yes"),E16,IF(G16="","",E16*G16)) | K16: =IFERROR(AND(OR(INDEX('Question Restrictions'!$D:$D,MATCH($B16,'Question Restrictions'!$C:$C,0))="All",ISNUMBER(SEARCH('Project Information'!$C$10,INDEX('Question Restrictions'!$D:$D,MATCH($B16,'Question Restrictions'!$C:$C,0))))),OR(INDEX('Question Restrictions'!$E:$E,MATCH($B16,'Question Restrictions'!$C:$C,0))="All",ISNUMBER(SEARCH('Project Information'!$C$11,INDEX('Question Restrictions'!$E:$E,MATCH($B16,'Question Restrictions'!$C:$C,0))))),OR(INDEX('Question Restrictions'!$F:$F,MATCH($B16,'Question Restrictions'!$C:$C,0))="All",ISNUMBER(SEARCH('Project Information'!$C$12,INDEX('Question Restrictions'!$F:$F,MATCH($B16,'Question Restrictions'!$C:$C,0))))),INDEX('Question Restrictions'!$G:$G,MATCH($B16,'Question Restrictions'!$C:$C,0))="Yes"),TRUE())
A17: 5 | B17: =INDEX(Translations!$D:$ZZ, MATCH(28,Translations!$A:$A,0), MATCH('Project Information'!$C$4,Translations!$D$1:$ZZ$1,0)) | C17: =INDEX(Translations!$D:$ZZ, MATCH(29,Translations!$A:$A,0), MATCH('Project Information'!$C$4,Translations!$D$1:$ZZ$1,0)) | D17: =INDEX(Translations!$D:$ZZ, MATCH(27,Translations!$A:$A,0), MATCH('Project Information'!$C$4,Translations!$D$1:$ZZ$1,0)) | E17: 5 | H17: =IF(OR(TRIM(F17)="Evet",TRIM(F17)="Yes"),E17,IF(G17="","",E17*G17)) | K17: =IFERROR(AND(OR(INDEX('Question Restrictions'!$D:$D,MATCH($B17,'Question Restrictions'!$C:$C,0))="All",ISNUMBER(SEARCH('Project Information'!$C$10,INDEX('Question Restrictions'!$D:$D,MATCH($B17,'Question Restrictions'!$C:$C,0))))),OR(INDEX('Question Restrictions'!$E:$E,MATCH($B17,'Question Restrictions'!$C:$C,0))="All",ISNUMBER(SEARCH('Project Information'!$C$11,INDEX('Question Restrictions'!$E:$E,MATCH($B17,'Question Restrictions'!$C:$C,0))))),OR(INDEX('Question Restrictions'!$F:$F,MATCH($B17,'Question Restrictions'!$C:$C,0))="All",ISNUMBER(SEARCH('Project Information'!$C$12,INDEX('Question Restrictions'!$F:$F,MATCH($B17,'Question Restrictions'!$C:$C,0))))),INDEX('Question Restrictions'!$G:$G,MATCH($B17,'Question Restrictions'!$C:$C,0))="Yes"),TRUE())
A18: 6 | B18: =INDEX(Translations!$D:$ZZ, MATCH(44,Translations!$A:$A,0), MATCH('Project Information'!$C$4,Translations!$D$1:$ZZ$1,0)) | C18: =INDEX(Translations!$D:$ZZ, MATCH(45,Translations!$A:$A,0), MATCH('Project Information'!$C$4,Translations!$D$1:$ZZ$1,0)) | D18: =INDEX(Translations!$D:$ZZ, MATCH(27,Translations!$A:$A,0), MATCH('Project Information'!$C$4,Translations!$D$1:$ZZ$1,0)) | E18: 5 | H18: =IF(OR(TRIM(F18)="Evet",TRIM(F18)="Yes"),E18,IF(G18="","",E18*G18)) | K18: =IFERROR(AND(OR(INDEX('Question Restrictions'!$D:$D,MATCH($B18,'Question Restrictions'!$C:$C,0))="All",ISNUMBER(SEARCH('Project Information'!$C$10,INDEX('Question Restrictions'!$D:$D,MATCH($B18,'Question Restrictions'!$C:$C,0))))),OR(INDEX('Question Restrictions'!$E:$E,MATCH($B18,'Question Restrictions'!$C:$C,0))="All",ISNUMBER(SEARCH('Project Information'!$C$11,INDEX('Question Restrictions'!$E:$E,MATCH($B18,'Question Restrictions'!$C:$C,0))))),OR(INDEX('Question Restrictions'!$F:$F,MATCH($B18,'Question Restrictions'!$C:$C,0))="All",ISNUMBER(SEARCH('Project Information'!$C$12,INDEX('Question Restrictions'!$F:$F,MATCH($B18,'Question Restrictions'!$C:$C,0))))),INDEX('Question Restrictions'!$G:$G,MATCH($B18,'Question Restrictions'!$C:$C,0))="Yes"),TRUE())
A19: 7 | B19: =INDEX(Translations!$D:$ZZ, MATCH(32,Translations!$A:$A,0), MATCH('Project Information'!$C$4,Translations!$D$1:$ZZ$1,0)) | C19: =INDEX(Translations!$D:$ZZ, MATCH(33,Translations!$A:$A,0), MATCH('Project Information'!$C$4,Translations!$D$1:$ZZ$1,0)) | D19: =INDEX(Translations!$D:$ZZ, MATCH(34,Translations!$A:$A,0), MATCH('Project Information'!$C$4,Translations!$D$1:$ZZ$1,0)) | E19: 15 | H19: =IF(OR(TRIM(F19)="Evet",TRIM(F19)="Yes"),E19,IF(G19="","",E19*G19)) | K19: =IFERROR(AND(OR(INDEX('Question Restrictions'!$D:$D,MATCH($B19,'Question Restrictions'!$C:$C,0))="All",ISNUMBER(SEARCH('Project Information'!$C$10,INDEX('Question Restrictions'!$D:$D,MATCH($B19,'Question Restrictions'!$C:$C,0))))),OR(INDEX('Question Restrictions'!$E:$E,MATCH($B19,'Question Restrictions'!$C:$C,0))="All",ISNUMBER(SEARCH('Project Information'!$C$11,INDEX('Question Restrictions'!$E:$E,MATCH($B19,'Question Restrictions'!$C:$C,0))))),OR(INDEX('Question Restrictions'!$F:$F,MATCH($B19,'Question Restrictions'!$C:$C,0))="All",ISNUMBER(SEARCH('Project Information'!$C$12,INDEX('Question Restrictions'!$F:$F,MATCH($B19,'Question Restrictions'!$C:$C,0))))),INDEX('Question Restrictions'!$G:$G,MATCH($B19,'Question Restrictions'!$C:$C,0))="Yes"),TRUE())
A20: 8 | B20: =INDEX(Translations!$D:$ZZ, MATCH(35,Translations!$A:$A,0), MATCH('Project Information'!$C$4,Translations!$D$1:$ZZ$1,0)) | C20: =INDEX(Translations!$D:$ZZ, MATCH(36,Translations!$A:$A,0), MATCH('Project Information'!$C$4,Translations!$D$1:$ZZ$1,0)) | D20: =INDEX(Translations!$D:$ZZ, MATCH(34,Translations!$A:$A,0), MATCH('Project Information'!$C$4,Translations!$D$1:$ZZ$1,0)) | E20: 20 | H20: =IF(OR(TRIM(F20)="Evet",TRIM(F20)="Yes"),E20,IF(G20="","",E20*G20)) | K20: =IFERROR(AND(OR(INDEX('Question Restrictions'!$D:$D,MATCH($B20,'Question Restrictions'!$C:$C,0))="All",ISNUMBER(SEARCH('Project Information'!$C$10,INDEX('Question Restrictions'!$D:$D,MATCH($B20,'Question Restrictions'!$C:$C,0))))),OR(INDEX('Question Restrictions'!$E:$E,MATCH($B20,'Question Restrictions'!$C:$C,0))="All",ISNUMBER(SEARCH('Project Information'!$C$11,INDEX('Question Restrictions'!$E:$E,MATCH($B20,'Question Restrictions'!$C:$C,0))))),OR(INDEX('Question Restrictions'!$F:$F,MATCH($B20,'Question Restrictions'!$C:$C,0))="All",ISNUMBER(SEARCH('Project Information'!$C$12,INDEX('Question Restrictions'!$F:$F,MATCH($B20,'Question Restrictions'!$C:$C,0))))),INDEX('Question Restrictions'!$G:$G,MATCH($B20,'Question Restrictions'!$C:$C,0))="Yes"),TRUE())
A21: 9 | B21: =INDEX(Translations!$D:$ZZ, MATCH(37,Translations!$A:$A,0), MATCH('Project Information'!$C$4,Translations!$D$1:$ZZ$1,0)) | C21: =INDEX(Translations!$D:$ZZ, MATCH(38,Translations!$A:$A,0), MATCH('Project Information'!$C$4,Translations!$D$1:$ZZ$1,0)) | D21: =INDEX(Translations!$D:$ZZ, MATCH(34,Translations!$A:$A,0), MATCH('Project Information'!$C$4,Translations!$D$1:$ZZ$1,0)) | E21: 30 | H21: =IF(OR(TRIM(F21)="Evet",TRIM(F21)="Yes"),E21,IF(G21="","",E21*G21)) | K21: =IFERROR(AND(OR(INDEX('Question Restrictions'!$D:$D,MATCH($B21,'Question Restrictions'!$C:$C,0))="All",ISNUMBER(SEARCH('Project Information'!$C$10,INDEX('Question Restrictions'!$D:$D,MATCH($B21,'Question Restrictions'!$C:$C,0))))),OR(INDEX('Question Restrictions'!$E:$E,MATCH($B21,'Question Restrictions'!$C:$C,0))="All",ISNUMBER(SEARCH('Project Information'!$C$11,INDEX('Question Restrictions'!$E:$E,MATCH($B21,'Question Restrictions'!$C:$C,0))))),OR(INDEX('Question Restrictions'!$F:$F,MATCH($B21,'Question Restrictions'!$C:$C,0))="All",ISNUMBER(SEARCH('Project Information'!$C$12,INDEX('Question Restrictions'!$F:$F,MATCH($B21,'Question Restrictions'!$C:$C,0))))),INDEX('Question Restrictions'!$G:$G,MATCH($B21,'Question Restrictions'!$C:$C,0))="Yes"),TRUE())
A22: 10 | B22: =INDEX(Translations!$D:$ZZ, MATCH(40,Translations!$A:$A,0), MATCH('Project Information'!$C$4,Translations!$D$1:$ZZ$1,0)) | C22: =INDEX(Translations!$D:$ZZ, MATCH(41,Translations!$A:$A,0), MATCH('Project Information'!$C$4,Translations!$D$1:$ZZ$1,0)) | D22: =INDEX(Translations!$D:$ZZ, MATCH(34,Translations!$A:$A,0), MATCH('Project Information'!$C$4,Translations!$D$1:$ZZ$1,0)) | E22: 15 | H22: =IF(OR(TRIM(F22)="Evet",TRIM(F22)="Yes"),E22,IF(G22="","",E22*G22)) | K22: =IFERROR(AND(OR(INDEX('Question Restrictions'!$D:$D,MATCH($B22,'Question Restrictions'!$C:$C,0))="All",ISNUMBER(SEARCH('Project Information'!$C$10,INDEX('Question Restrictions'!$D:$D,MATCH($B22,'Question Restrictions'!$C:$C,0))))),OR(INDEX('Question Restrictions'!$E:$E,MATCH($B22,'Question Restrictions'!$C:$C,0))="All",ISNUMBER(SEARCH('Project Information'!$C$11,INDEX('Question Restrictions'!$E:$E,MATCH($B22,'Question Restrictions'!$C:$C,0))))),OR(INDEX('Question Restrictions'!$F:$F,MATCH($B22,'Question Restrictions'!$C:$C,0))="All",ISNUMBER(SEARCH('Project Information'!$C$12,INDEX('Question Restrictions'!$F:$F,MATCH($B22,'Question Restrictions'!$C:$C,0))))),INDEX('Question Restrictions'!$G:$G,MATCH($B22,'Question Restrictions'!$C:$C,0))="Yes"),TRUE())
A23: 11 | B23: =INDEX(Translations!$D:$ZZ, MATCH(46,Translations!$A:$A,0), MATCH('Project Information'!$C$4,Translations!$D$1:$ZZ$1,0)) | C23: =INDEX(Translations!$D:$ZZ, MATCH(47,Translations!$A:$A,0), MATCH('Project Information'!$C$4,Translations!$D$1:$ZZ$1,0)) | D23: =INDEX(Translations!$D:$ZZ, MATCH(34,Translations!$A:$A,0), MATCH('Project Information'!$C$4,Translations!$D$1:$ZZ$1,0)) | E23: 5 | H23: =IF(OR(TRIM(F23)="Evet",TRIM(F23)="Yes"),E23,IF(G23="","",E23*G23)) | K23: =IFERROR(AND(OR(INDEX('Question Restrictions'!$D:$D,MATCH($B23,'Question Restrictions'!$C:$C,0))="All",ISNUMBER(SEARCH('Project Information'!$C$10,INDEX('Question Restrictions'!$D:$D,MATCH($B23,'Question Restrictions'!$C:$C,0))))),OR(INDEX('Question Restrictions'!$E:$E,MATCH($B23,'Question Restrictions'!$C:$C,0))="All",ISNUMBER(SEARCH('Project Information'!$C$11,INDEX('Question Restrictions'!$E:$E,MATCH($B23,'Question Restrictions'!$C:$C,0))))),OR(INDEX('Question Restrictions'!$F:$F,MATCH($B23,'Question Restrictions'!$C:$C,0))="All",ISNUMBER(SEARCH('Project Information'!$C$12,INDEX('Question Restrictions'!$F:$F,MATCH($B23,'Question Restrictions'!$C:$C,0))))),INDEX('Question Restrictions'!$G:$G,MATCH($B23,'Question Restrictions'!$C:$C,0))="Yes"),TRUE())
A24: 12 | B24: =INDEX(Translations!$D:$ZZ, MATCH(253,Translations!$A:$A,0), MATCH('Project Information'!$C$4,Translations!$D$1:$ZZ$1,0)) | C24: =INDEX(Translations!$D:$ZZ, MATCH(254,Translations!$A:$A,0), MATCH('Project Information'!$C$4,Translations!$D$1:$ZZ$1,0)) | D24: =INDEX(Translations!$D:$ZZ, MATCH(172,Translations!$A:$A,0), MATCH('Project Information'!$C$4,Translations!$D$1:$ZZ$1,0)) | H24: =IF(OR(TRIM(F24)="Evet",TRIM(F24)="Yes"),E24,IF(G24="","",E24*G24)) | K24: =IFERROR(AND(OR(INDEX('Question Restrictions'!$D:$D,MATCH($B24,'Question Restrictions'!$C:$C,0))="All",ISNUMBER(SEARCH('Project Information'!$C$10,INDEX('Question Restrictions'!$D:$D,MATCH($B24,'Question Restrictions'!$C:$C,0))))),OR(INDEX('Question Restrictions'!$E:$E,MATCH($B24,'Question Restrictions'!$C:$C,0))="All",ISNUMBER(SEARCH('Project Information'!$C$11,INDEX('Question Restrictions'!$E:$E,MATCH($B24,'Question Restrictions'!$C:$C,0))))),OR(INDEX('Question Restrictions'!$F:$F,MATCH($B24,'Question Restrictions'!$C:$C,0))="All",ISNUMBER(SEARCH('Project Information'!$C$12,INDEX('Question Restrictions'!$F:$F,MATCH($B24,'Question Restrictions'!$C:$C,0))))),INDEX('Question Restrictions'!$G:$G,MATCH($B24,'Question Restrictions'!$C:$C,0))="Yes"),TRUE())
A25: 13 | B25: =INDEX(Translations!$D:$ZZ, MATCH(257,Translations!$A:$A,0), MATCH('Project Information'!$C$4,Translations!$D$1:$ZZ$1,0)) | C25: =INDEX(Translations!$D:$ZZ, MATCH(258,Translations!$A:$A,0), MATCH('Project Information'!$C$4,Translations!$D$1:$ZZ$1,0)) | D25: =INDEX(Translations!$D:$ZZ, MATCH(172,Translations!$A:$A,0), MATCH('Project Information'!$C$4,Translations!$D$1:$ZZ$1,0)) | H25: =IF(OR(TRIM(F25)="Evet",TRIM(F25)="Yes"),E25,IF(G25="","",E25*G25)) | K25: =IFERROR(AND(OR(INDEX('Question Restrictions'!$D:$D,MATCH($B25,'Question Restrictions'!$C:$C,0))="All",ISNUMBER(SEARCH('Project Information'!$C$10,INDEX('Question Restrictions'!$D:$D,MATCH($B25,'Question Restrictions'!$C:$C,0))))),OR(INDEX('Question Restrictions'!$E:$E,MATCH($B25,'Question Restrictions'!$C:$C,0))="All",ISNUMBER(SEARCH('Project Information'!$C$11,INDEX('Question Restrictions'!$E:$E,MATCH($B25,'Question Restrictions'!$C:$C,0))))),OR(INDEX('Question Restrictions'!$F:$F,MATCH($B25,'Question Restrictions'!$C:$C,0))="All",ISNUMBER(SEARCH('Project Information'!$C$12,INDEX('Question Restrictions'!$F:$F,MATCH($B25,'Question Restrictions'!$C:$C,0))))),INDEX('Question Restrictions'!$G:$G,MATCH($B25,'Question Restrictions'!$C:$C,0))="Yes"),TRUE())
A26: 14 | B26: =INDEX(Translations!$D:$ZZ, MATCH(259,Translations!$A:$A,0), MATCH('Project Information'!$C$4,Translations!$D$1:$ZZ$1,0)) | C26: =INDEX(Translations!$D:$ZZ, MATCH(260,Translations!$A:$A,0), MATCH('Project Information'!$C$4,Translations!$D$1:$ZZ$1,0)) | D26: =INDEX(Translations!$D:$ZZ, MATCH(172,Translations!$A:$A,0), MATCH('Project Information'!$C$4,Translations!$D$1:$ZZ$1,0)) | H26: =IF(OR(TRIM(F26)="Evet",TRIM(F26)="Yes"),E26,IF(G26="","",E26*G26)) | K26: =IFERROR(AND(OR(INDEX('Question Restrictions'!$D:$D,MATCH($B26,'Question Restrictions'!$C:$C,0))="All",ISNUMBER(SEARCH('Project Information'!$C$10,INDEX('Question Restrictions'!$D:$D,MATCH($B26,'Question Restrictions'!$C:$C,0))))),OR(INDEX('Question Restrictions'!$E:$E,MATCH($B26,'Question Restrictions'!$C:$C,0))="All",ISNUMBER(SEARCH('Project Information'!$C$11,INDEX('Question Restrictions'!$E:$E,MATCH($B26,'Question Restrictions'!$C:$C,0))))),OR(INDEX('Question Restrictions'!$F:$F,MATCH($B26,'Question Restrictions'!$C:$C,0))="All",ISNUMBER(SEARCH('Project Information'!$C$12,INDEX('Question Restrictions'!$F:$F,MATCH($B26,'Question Restrictions'!$C:$C,0))))),INDEX('Question Restrictions'!$G:$G,MATCH($B26,'Question Restrictions'!$C:$C,0))="Yes"),TRUE())
A27: 15 | B27: =INDEX(Translations!$D:$ZZ, MATCH(261,Translations!$A:$A,0), MATCH('Project Information'!$C$4,Translations!$D$1:$ZZ$1,0)) | C27: =INDEX(Translations!$D:$ZZ, MATCH(262,Translations!$A:$A,0), MATCH('Project Information'!$C$4,Translations!$D$1:$ZZ$1,0)) | D27: =INDEX(Translations!$D:$ZZ, MATCH(172,Translations!$A:$A,0), MATCH('Project Information'!$C$4,Translations!$D$1:$ZZ$1,0)) | H27: =IF(OR(TRIM(F27)="Evet",TRIM(F27)="Yes"),E27,IF(G27="","",E27*G27)) | K27: =IFERROR(AND(OR(INDEX('Question Restrictions'!$D:$D,MATCH($B27,'Question Restrictions'!$C:$C,0))="All",ISNUMBER(SEARCH('Project Information'!$C$10,INDEX('Question Restrictions'!$D:$D,MATCH($B27,'Question Restrictions'!$C:$C,0))))),OR(INDEX('Question Restrictions'!$E:$E,MATCH($B27,'Question Restrictions'!$C:$C,0))="All",ISNUMBER(SEARCH('Project Information'!$C$11,INDEX('Question Restrictions'!$E:$E,MATCH($B27,'Question Restrictions'!$C:$C,0))))),OR(INDEX('Question Restrictions'!$F:$F,MATCH($B27,'Question Restrictions'!$C:$C,0))="All",ISNUMBER(SEARCH('Project Information'!$C$12,INDEX('Question Restrictions'!$F:$F,MATCH($B27,'Question Restrictions'!$C:$C,0))))),INDEX('Question Restrictions'!$G:$G,MATCH($B27,'Question Restrictions'!$C:$C,0))="Yes"),TRUE())
A28: 16 | B28: =INDEX(Translations!$D:$ZZ, MATCH(265,Translations!$A:$A,0), MATCH('Project Information'!$C$4,Translations!$D$1:$ZZ$1,0)) | C28: =INDEX(Translations!$D:$ZZ, MATCH(266,Translations!$A:$A,0), MATCH('Project Information'!$C$4,Translations!$D$1:$ZZ$1,0)) | D28: =INDEX(Translations!$D:$ZZ, MATCH(172,Translations!$A:$A,0), MATCH('Project Information'!$C$4,Translations!$D$1:$ZZ$1,0)) | H28: =IF(OR(TRIM(F28)="Evet",TRIM(F28)="Yes"),E28,IF(G28="","",E28*G28)) | K28: =IFERROR(AND(OR(INDEX('Question Restrictions'!$D:$D,MATCH($B28,'Question Restrictions'!$C:$C,0))="All",ISNUMBER(SEARCH('Project Information'!$C$10,INDEX('Question Restrictions'!$D:$D,MATCH($B28,'Question Restrictions'!$C:$C,0))))),OR(INDEX('Question Restrictions'!$E:$E,MATCH($B28,'Question Restrictions'!$C:$C,0))="All",ISNUMBER(SEARCH('Project Information'!$C$11,INDEX('Question Restrictions'!$E:$E,MATCH($B28,'Question Restrictions'!$C:$C,0))))),OR(INDEX('Question Restrictions'!$F:$F,MATCH($B28,'Question Restrictions'!$C:$C,0))="All",ISNUMBER(SEARCH('Project Information'!$C$12,INDEX('Question Restrictions'!$F:$F,MATCH($B28,'Question Restrictions'!$C:$C,0))))),INDEX('Question Restrictions'!$G:$G,MATCH($B28,'Question Restrictions'!$C:$C,0))="Yes"),TRUE())
A29: 17 | B29: =INDEX(Translations!$D:$ZZ, MATCH(185,Translations!$A:$A,0), MATCH('Project Information'!$C$4,Translations!$D$1:$ZZ$1,0)) | C29: =INDEX(Translations!$D:$ZZ, MATCH(186,Translations!$A:$A,0), MATCH('Project Information'!$C$4,Translations!$D$1:$ZZ$1,0)) | D29: =INDEX(Translations!$D:$ZZ, MATCH(27,Translations!$A:$A,0), MATCH('Project Information'!$C$4,Translations!$D$1:$ZZ$1,0)) | H29: =IF(OR(TRIM(F29)="Evet",TRIM(F29)="Yes"),E29,IF(G29="","",E29*G29)) | K29: =IFERROR(AND(OR(INDEX('Question Restrictions'!$D:$D,MATCH($B29,'Question Restrictions'!$C:$C,0))="All",ISNUMBER(SEARCH('Project Information'!$C$10,INDEX('Question Restrictions'!$D:$D,MATCH($B29,'Question Restrictions'!$C:$C,0))))),OR(INDEX('Question Restrictions'!$E:$E,MATCH($B29,'Question Restrictions'!$C:$C,0))="All",ISNUMBER(SEARCH('Project Information'!$C$11,INDEX('Question Restrictions'!$E:$E,MATCH($B29,'Question Restrictions'!$C:$C,0))))),OR(INDEX('Question Restrictions'!$F:$F,MATCH($B29,'Question Restrictions'!$C:$C,0))="All",ISNUMBER(SEARCH('Project Information'!$C$12,INDEX('Question Restrictions'!$F:$F,MATCH($B29,'Question Restrictions'!$C:$C,0))))),INDEX('Question Restrictions'!$G:$G,MATCH($B29,'Question Restrictions'!$C:$C,0))="Yes"),TRUE())
A30: 18 | B30: =INDEX(Translations!$D:$ZZ, MATCH(187,Translations!$A:$A,0), MATCH('Project Information'!$C$4,Translations!$D$1:$ZZ$1,0)) | C30: =INDEX(Translations!$D:$ZZ, MATCH(188,Translations!$A:$A,0), MATCH('Project Information'!$C$4,Translations!$D$1:$ZZ$1,0)) | D30: =INDEX(Translations!$D:$ZZ, MATCH(27,Translations!$A:$A,0), MATCH('Project Information'!$C$4,Translations!$D$1:$ZZ$1,0)) | H30: =IF(OR(TRIM(F30)="Evet",TRIM(F30)="Yes"),E30,IF(G30="","",E30*G30)) | K30: =IFERROR(AND(OR(INDEX('Question Restrictions'!$D:$D,MATCH($B30,'Question Restrictions'!$C:$C,0))="All",ISNUMBER(SEARCH('Project Information'!$C$10,INDEX('Question Restrictions'!$D:$D,MATCH($B30,'Question Restrictions'!$C:$C,0))))),OR(INDEX('Question Restrictions'!$E:$E,MATCH($B30,'Question Restrictions'!$C:$C,0))="All",ISNUMBER(SEARCH('Project Information'!$C$11,INDEX('Question Restrictions'!$E:$E,MATCH($B30,'Question Restrictions'!$C:$C,0))))),OR(INDEX('Question Restrictions'!$F:$F,MATCH($B30,'Question Restrictions'!$C:$C,0))="All",ISNUMBER(SEARCH('Project Information'!$C$12,INDEX('Question Restrictions'!$F:$F,MATCH($B30,'Question Restrictions'!$C:$C,0))))),INDEX('Question Restrictions'!$G:$G,MATCH($B30,'Question Restrictions'!$C:$C,0))="Yes"),TRUE())
A31: 19 | B31: =INDEX(Translations!$D:$ZZ, MATCH(183,Translations!$A:$A,0), MATCH('Project Information'!$C$4,Translations!$D$1:$ZZ$1,0)) | C31: =INDEX(Translations!$D:$ZZ, MATCH(184,Translations!$A:$A,0), MATCH('Project Information'!$C$4,Translations!$D$1:$ZZ$1,0)) | D31: =INDEX(Translations!$D:$ZZ, MATCH(172,Translations!$A:$A,0), MATCH('Project Information'!$C$4,Translations!$D$1:$ZZ$1,0)) | H31: =IF(OR(TRIM(F31)="Evet",TRIM(F31)="Yes"),E31,IF(G31="","",E31*G31)) | K31: =IFERROR(AND(OR(INDEX('Question Restrictions'!$D:$D,MATCH($B31,'Question Restrictions'!$C:$C,0))="All",ISNUMBER(SEARCH('Project Information'!$C$10,INDEX('Question Restrictions'!$D:$D,MATCH($B31,'Question Restrictions'!$C:$C,0))))),OR(INDEX('Question Restrictions'!$E:$E,MATCH($B31,'Question Restrictions'!$C:$C,0))="All",ISNUMBER(SEARCH('Project Information'!$C$11,INDEX('Question Restrictions'!$E:$E,MATCH($B31,'Question Restrictions'!$C:$C,0))))),OR(INDEX('Question Restrictions'!$F:$F,MATCH($B31,'Question Restrictions'!$C:$C,0))="All",ISNUMBER(SEARCH('Project Information'!$C$12,INDEX('Question Restrictions'!$F:$F,MATCH($B31,'Question Restrictions'!$C:$C,0))))),INDEX('Question Restrictions'!$G:$G,MATCH($B31,'Question Restrictions'!$C:$C,0))="Yes"),TRUE())
A32: 20 | B32: =INDEX(Translations!$D:$ZZ, MATCH(193,Translations!$A:$A,0), MATCH('Project Information'!$C$4,Translations!$D$1:$ZZ$1,0)) | C32: =INDEX(Translations!$D:$ZZ, MATCH(194,Translations!$A:$A,0), MATCH('Project Information'!$C$4,Translations!$D$1:$ZZ$1,0)) | D32: =INDEX(Translations!$D:$ZZ, MATCH(172,Translations!$A:$A,0), MATCH('Project Information'!$C$4,Translations!$D$1:$ZZ$1,0)) | H32: =IF(OR(TRIM(F32)="Evet",TRIM(F32)="Yes"),E32,IF(G32="","",E32*G32)) | K32: =IFERROR(AND(OR(INDEX('Question Restrictions'!$D:$D,MATCH($B32,'Question Restrictions'!$C:$C,0))="All",ISNUMBER(SEARCH('Project Information'!$C$10,INDEX('Question Restrictions'!$D:$D,MATCH($B32,'Question Restrictions'!$C:$C,0))))),OR(INDEX('Question Restrictions'!$E:$E,MATCH($B32,'Question Restrictions'!$C:$C,0))="All",ISNUMBER(SEARCH('Project Information'!$C$11,INDEX('Question Restrictions'!$E:$E,MATCH($B32,'Question Restrictions'!$C:$C,0))))),OR(INDEX('Question Restrictions'!$F:$F,MATCH($B32,'Question Restrictions'!$C:$C,0))="All",ISNUMBER(SEARCH('Project Information'!$C$12,INDEX('Question Restrictions'!$F:$F,MATCH($B32,'Question Restrictions'!$C:$C,0))))),INDEX('Question Restrictions'!$G:$G,MATCH($B32,'Question Restrictions'!$C:$C,0))="Yes"),TRUE())
A33: 21 | B33: =INDEX(Translations!$D:$ZZ, MATCH(181,Translations!$A:$A,0), MATCH('Project Information'!$C$4,Translations!$D$1:$ZZ$1,0)) | C33: =INDEX(Translations!$D:$ZZ, MATCH(182,Translations!$A:$A,0), MATCH('Project Information'!$C$4,Translations!$D$1:$ZZ$1,0)) | D33: =INDEX(Translations!$D:$ZZ, MATCH(27,Translations!$A:$A,0), MATCH('Project Information'!$C$4,Translations!$D$1:$ZZ$1,0)) | H33: =IF(OR(TRIM(F33)="Evet",TRIM(F33)="Yes"),E33,IF(G33="","",E33*G33)) | K33: =IFERROR(AND(OR(INDEX('Question Restrictions'!$D:$D,MATCH($B33,'Question Restrictions'!$C:$C,0))="All",ISNUMBER(SEARCH('Project Information'!$C$10,INDEX('Question Restrictions'!$D:$D,MATCH($B33,'Question Restrictions'!$C:$C,0))))),OR(INDEX('Question Restrictions'!$E:$E,MATCH($B33,'Question Restrictions'!$C:$C,0))="All",ISNUMBER(SEARCH('Project Information'!$C$11,INDEX('Question Restrictions'!$E:$E,MATCH($B33,'Question Restrictions'!$C:$C,0))))),OR(INDEX('Question Restrictions'!$F:$F,MATCH($B33,'Question Restrictions'!$C:$C,0))="All",ISNUMBER(SEARCH('Project Information'!$C$12,INDEX('Question Restrictions'!$F:$F,MATCH($B33,'Question Restrictions'!$C:$C,0))))),INDEX('Question Restrictions'!$G:$G,MATCH($B33,'Question Restrictions'!$C:$C,0))="Yes"),TRUE())
A34: 22 | B34: =INDEX(Translations!$D:$ZZ, MATCH(177,Translations!$A:$A,0), MATCH('Project Information'!$C$4,Translations!$D$1:$ZZ$1,0)) | C34: =INDEX(Translations!$D:$ZZ, MATCH(178,Translations!$A:$A,0), MATCH('Project Information'!$C$4,Translations!$D$1:$ZZ$1,0)) | D34: =INDEX(Translations!$D:$ZZ, MATCH(27,Translations!$A:$A,0), MATCH('Project Information'!$C$4,Translations!$D$1:$ZZ$1,0)) | H34: =IF(OR(TRIM(F34)="Evet",TRIM(F34)="Yes"),E34,IF(G34="","",E34*G34)) | K34: =IFERROR(AND(OR(INDEX('Question Restrictions'!$D:$D,MATCH($B34,'Question Restrictions'!$C:$C,0))="All",ISNUMBER(SEARCH('Project Information'!$C$10,INDEX('Question Restrictions'!$D:$D,MATCH($B34,'Question Restrictions'!$C:$C,0))))),OR(INDEX('Question Restrictions'!$E:$E,MATCH($B34,'Question Restrictions'!$C:$C,0))="All",ISNUMBER(SEARCH('Project Information'!$C$11,INDEX('Question Restrictions'!$E:$E,MATCH($B34,'Question Restrictions'!$C:$C,0))))),OR(INDEX('Question Restrictions'!$F:$F,MATCH($B34,'Question Restrictions'!$C:$C,0))="All",ISNUMBER(SEARCH('Project Information'!$C$12,INDEX('Question Restrictions'!$F:$F,MATCH($B34,'Question Restrictions'!$C:$C,0))))),INDEX('Question Restrictions'!$G:$G,MATCH($B34,'Question Restrictions'!$C:$C,0))="Yes"),TRUE())
A35: 23 | B35: =INDEX(Translations!$D:$ZZ, MATCH(179,Translations!$A:$A,0), MATCH('Project Information'!$C$4,Translations!$D$1:$ZZ$1,0)) | C35: =INDEX(Translations!$D:$ZZ, MATCH(180,Translations!$A:$A,0), MATCH('Project Information'!$C$4,Translations!$D$1:$ZZ$1,0)) | D35: =INDEX(Translations!$D:$ZZ, MATCH(172,Translations!$A:$A,0), MATCH('Project Information'!$C$4,Translations!$D$1:$ZZ$1,0)) | H35: =IF(OR(TRIM(F35)="Evet",TRIM(F35)="Yes"),E35,IF(G35="","",E35*G35)) | K35: =IFERROR(AND(OR(INDEX('Question Restrictions'!$D:$D,MATCH($B35,'Question Restrictions'!$C:$C,0))="All",ISNUMBER(SEARCH('Project Information'!$C$10,INDEX('Question Restrictions'!$D:$D,MATCH($B35,'Question Restrictions'!$C:$C,0))))),OR(INDEX('Question Restrictions'!$E:$E,MATCH($B35,'Question Restrictions'!$C:$C,0))="All",ISNUMBER(SEARCH('Project Information'!$C$11,INDEX('Question Restrictions'!$E:$E,MATCH($B35,'Question Restrictions'!$C:$C,0))))),OR(INDEX('Question Restrictions'!$F:$F,MATCH($B35,'Question Restrictions'!$C:$C,0))="All",ISNUMBER(SEARCH('Project Information'!$C$12,INDEX('Question Restrictions'!$F:$F,MATCH($B35,'Question Restrictions'!$C:$C,0))))),INDEX('Question Restrictions'!$G:$G,MATCH($B35,'Question Restrictions'!$C:$C,0))="Yes"),TRUE())
A36: 24 | B36: =INDEX(Translations!$D:$ZZ, MATCH(189,Translations!$A:$A,0), MATCH('Project Information'!$C$4,Translations!$D$1:$ZZ$1,0)) | C36: =INDEX(Translations!$D:$ZZ, MATCH(190,Translations!$A:$A,0), MATCH('Project Information'!$C$4,Translations!$D$1:$ZZ$1,0)) | D36: =INDEX(Translations!$D:$ZZ, MATCH(172,Translations!$A:$A,0), MATCH('Project Information'!$C$4,Translations!$D$1:$ZZ$1,0)) | H36: =IF(OR(TRIM(F36)="Evet",TRIM(F36)="Yes"),E36,IF(G36="","",E36*G36)) | K36: =IFERROR(AND(OR(INDEX('Question Restrictions'!$D:$D,MATCH($B36,'Question Restrictions'!$C:$C,0))="All",ISNUMBER(SEARCH('Project Information'!$C$10,INDEX('Question Restrictions'!$D:$D,MATCH($B36,'Question Restrictions'!$C:$C,0))))),OR(INDEX('Question Restrictions'!$E:$E,MATCH($B36,'Question Restrictions'!$C:$C,0))="All",ISNUMBER(SEARCH('Project Information'!$C$11,INDEX('Question Restrictions'!$E:$E,MATCH($B36,'Question Restrictions'!$C:$C,0))))),OR(INDEX('Question Restrictions'!$F:$F,MATCH($B36,'Question Restrictions'!$C:$C,0))="All",ISNUMBER(SEARCH('Project Information'!$C$12,INDEX('Question Restrictions'!$F:$F,MATCH($B36,'Question Restrictions'!$C:$C,0))))),INDEX('Question Restrictions'!$G:$G,MATCH($B36,'Question Restrictions'!$C:$C,0))="Yes"),TRUE())
A37: 25 | B37: =INDEX(Translations!$D:$ZZ, MATCH(191,Translations!$A:$A,0), MATCH('Project Information'!$C$4,Translations!$D$1:$ZZ$1,0)) | C37: =INDEX(Translations!$D:$ZZ, MATCH(192,Translations!$A:$A,0), MATCH('Project Information'!$C$4,Translations!$D$1:$ZZ$1,0)) | D37: =INDEX(Translations!$D:$ZZ, MATCH(27,Translations!$A:$A,0), MATCH('Project Information'!$C$4,Translations!$D$1:$ZZ$1,0)) | H37: =IF(OR(TRIM(F37)="Evet",TRIM(F37)="Yes"),E37,IF(G37="","",E37*G37)) | K37: =IFERROR(AND(OR(INDEX('Question Restrictions'!$D:$D,MATCH($B37,'Question Restrictions'!$C:$C,0))="All",ISNUMBER(SEARCH('Project Information'!$C$10,INDEX('Question Restrictions'!$D:$D,MATCH($B37,'Question Restrictions'!$C:$C,0))))),OR(INDEX('Question Restrictions'!$E:$E,MATCH($B37,'Question Restrictions'!$C:$C,0))="All",ISNUMBER(SEARCH('Project Information'!$C$11,INDEX('Question Restrictions'!$E:$E,MATCH($B37,'Question Restrictions'!$C:$C,0))))),OR(INDEX('Question Restrictions'!$F:$F,MATCH($B37,'Question Restrictions'!$C:$C,0))="All",ISNUMBER(SEARCH('Project Information'!$C$12,INDEX('Question Restrictions'!$F:$F,MATCH($B37,'Question Restrictions'!$C:$C,0))))),INDEX('Question Restrictions'!$G:$G,MATCH($B37,'Question Restrictions'!$C:$C,0))="Yes"),TRUE())
A38: 26 | B38: =INDEX(Translations!$D:$ZZ, MATCH(195,Translations!$A:$A,0), MATCH('Project Information'!$C$4,Translations!$D$1:$ZZ$1,0)) | C38: =INDEX(Translations!$D:$ZZ, MATCH(196,Translations!$A:$A,0), MATCH('Project Information'!$C$4,Translations!$D$1:$ZZ$1,0)) | D38: =INDEX(Translations!$D:$ZZ, MATCH(172,Translations!$A:$A,0), MATCH('Project Information'!$C$4,Translations!$D$1:$ZZ$1,0)) | H38: =IF(OR(TRIM(F38)="Evet",TRIM(F38)="Yes"),E38,IF(G38="","",E38*G38)) | K38: =IFERROR(AND(OR(INDEX('Question Restrictions'!$D:$D,MATCH($B38,'Question Restrictions'!$C:$C,0))="All",ISNUMBER(SEARCH('Project Information'!$C$10,INDEX('Question Restrictions'!$D:$D,MATCH($B38,'Question Restrictions'!$C:$C,0))))),OR(INDEX('Question Restrictions'!$E:$E,MATCH($B38,'Question Restrictions'!$C:$C,0))="All",ISNUMBER(SEARCH('Project Information'!$C$11,INDEX('Question Restrictions'!$E:$E,MATCH($B38,'Question Restrictions'!$C:$C,0))))),OR(INDEX('Question Restrictions'!$F:$F,MATCH($B38,'Question Restrictions'!$C:$C,0))="All",ISNUMBER(SEARCH('Project Information'!$C$12,INDEX('Question Restrictions'!$F:$F,MATCH($B38,'Question Restrictions'!$C:$C,0))))),INDEX('Question Restrictions'!$G:$G,MATCH($B38,'Question Restrictions'!$C:$C,0))="Yes"),TRUE())
A39: 27 | B39: =INDEX(Translations!$D:$ZZ, MATCH(197,Translations!$A:$A,0), MATCH('Project Information'!$C$4,Translations!$D$1:$ZZ$1,0)) | C39: =INDEX(Translations!$D:$ZZ, MATCH(198,Translations!$A:$A,0), MATCH('Project Information'!$C$4,Translations!$D$1:$ZZ$1,0)) | D39: =INDEX(Translations!$D:$ZZ, MATCH(172,Translations!$A:$A,0), MATCH('Project Information'!$C$4,Translations!$D$1:$ZZ$1,0)) | H39: =IF(OR(TRIM(F39)="Evet",TRIM(F39)="Yes"),E39,IF(G39="","",E39*G39)) | K39: =IFERROR(AND(OR(INDEX('Question Restrictions'!$D:$D,MATCH($B39,'Question Restrictions'!$C:$C,0))="All",ISNUMBER(SEARCH('Project Information'!$C$10,INDEX('Question Restrictions'!$D:$D,MATCH($B39,'Question Restrictions'!$C:$C,0))))),OR(INDEX('Question Restrictions'!$E:$E,MATCH($B39,'Question Restrictions'!$C:$C,0))="All",ISNUMBER(SEARCH('Project Information'!$C$11,INDEX('Question Restrictions'!$E:$E,MATCH($B39,'Question Restrictions'!$C:$C,0))))),OR(INDEX('Question Restrictions'!$F:$F,MATCH($B39,'Question Restrictions'!$C:$C,0))="All",ISNUMBER(SEARCH('Project Information'!$C$12,INDEX('Question Restrictions'!$F:$F,MATCH($B39,'Question Restrictions'!$C:$C,0))))),INDEX('Question Restrictions'!$G:$G,MATCH($B39,'Question Restrictions'!$C:$C,0))="Yes"),TRUE())
A40: 28 | B40: =INDEX(Translations!$D:$ZZ, MATCH(199,Translations!$A:$A,0), MATCH('Project Information'!$C$4,Translations!$D$1:$ZZ$1,0)) | C40: =INDEX(Translations!$D:$ZZ, MATCH(200,Translations!$A:$A,0), MATCH('Project Information'!$C$4,Translations!$D$1:$ZZ$1,0)) | D40: =INDEX(Translations!$D:$ZZ, MATCH(172,Translations!$A:$A,0), MATCH('Project Information'!$C$4,Translations!$D$1:$ZZ$1,0)) | H40: =IF(OR(TRIM(F40)="Evet",TRIM(F40)="Yes"),E40,IF(G40="","",E40*G40)) | K40: =IFERROR(AND(OR(INDEX('Question Restrictions'!$D:$D,MATCH($B40,'Question Restrictions'!$C:$C,0))="All",ISNUMBER(SEARCH('Project Information'!$C$10,INDEX('Question Restrictions'!$D:$D,MATCH($B40,'Question Restrictions'!$C:$C,0))))),OR(INDEX('Question Restrictions'!$E:$E,MATCH($B40,'Question Restrictions'!$C:$C,0))="All",ISNUMBER(SEARCH('Project Information'!$C$11,INDEX('Question Restrictions'!$E:$E,MATCH($B40,'Question Restrictions'!$C:$C,0))))),OR(INDEX('Question Restrictions'!$F:$F,MATCH($B40,'Question Restrictions'!$C:$C,0))="All",ISNUMBER(SEARCH('Project Information'!$C$12,INDEX('Question Restrictions'!$F:$F,MATCH($B40,'Question Restrictions'!$C:$C,0))))),INDEX('Question Restrictions'!$G:$G,MATCH($B40,'Question Restrictions'!$C:$C,0))="Yes"),TRUE())
A41: 29 | B41: =INDEX(Translations!$D:$ZZ, MATCH(255,Translations!$A:$A,0), MATCH('Project Information'!$C$4,Translations!$D$1:$ZZ$1,0)) | C41: =INDEX(Translations!$D:$ZZ, MATCH(256,Translations!$A:$A,0), MATCH('Project Information'!$C$4,Translations!$D$1:$ZZ$1,0)) | D41: =INDEX(Translations!$D:$ZZ, MATCH(172,Translations!$A:$A,0), MATCH('Project Information'!$C$4,Translations!$D$1:$ZZ$1,0)) | H41: =IF(OR(TRIM(F41)="Evet",TRIM(F41)="Yes"),E41,IF(G41="","",E41*G41)) | K41: =IFERROR(AND(OR(INDEX('Question Restrictions'!$D:$D,MATCH($B41,'Question Restrictions'!$C:$C,0))="All",ISNUMBER(SEARCH('Project Information'!$C$10,INDEX('Question Restrictions'!$D:$D,MATCH($B41,'Question Restrictions'!$C:$C,0))))),OR(INDEX('Question Restrictions'!$E:$E,MATCH($B41,'Question Restrictions'!$C:$C,0))="All",ISNUMBER(SEARCH('Project Information'!$C$11,INDEX('Question Restrictions'!$E:$E,MATCH($B41,'Question Restrictions'!$C:$C,0))))),OR(INDEX('Question Restrictions'!$F:$F,MATCH($B41,'Question Restrictions'!$C:$C,0))="All",ISNUMBER(SEARCH('Project Information'!$C$12,INDEX('Question Restrictions'!$F:$F,MATCH($B41,'Question Restrictions'!$C:$C,0))))),INDEX('Question Restrictions'!$G:$G,MATCH($B41,'Question Restrictions'!$C:$C,0))="Yes"),TRUE())
A42: 30 | B42: =INDEX(Translations!$D:$ZZ, MATCH(203,Translations!$A:$A,0), MATCH('Project Information'!$C$4,Translations!$D$1:$ZZ$1,0)) | C42: =INDEX(Translations!$D:$ZZ, MATCH(204,Translations!$A:$A,0), MATCH('Project Information'!$C$4,Translations!$D$1:$ZZ$1,0)) | D42: =INDEX(Translations!$D:$ZZ, MATCH(172,Translations!$A:$A,0), MATCH('Project Information'!$C$4,Translations!$D$1:$ZZ$1,0)) | H42: =IF(OR(TRIM(F42)="Evet",TRIM(F42)="Yes"),E42,IF(G42="","",E42*G42)) | K42: =IFERROR(AND(OR(INDEX('Question Restrictions'!$D:$D,MATCH($B42,'Question Restrictions'!$C:$C,0))="All",ISNUMBER(SEARCH('Project Information'!$C$10,INDEX('Question Restrictions'!$D:$D,MATCH($B42,'Question Restrictions'!$C:$C,0))))),OR(INDEX('Question Restrictions'!$E:$E,MATCH($B42,'Question Restrictions'!$C:$C,0))="All",ISNUMBER(SEARCH('Project Information'!$C$11,INDEX('Question Restrictions'!$E:$E,MATCH($B42,'Question Restrictions'!$C:$C,0))))),OR(INDEX('Question Restrictions'!$F:$F,MATCH($B42,'Question Restrictions'!$C:$C,0))="All",ISNUMBER(SEARCH('Project Information'!$C$12,INDEX('Question Restrictions'!$F:$F,MATCH($B42,'Question Restrictions'!$C:$C,0))))),INDEX('Question Restrictions'!$G:$G,MATCH($B42,'Question Restrictions'!$C:$C,0))="Yes"),TRUE())
...

Sheet Development
A1: =INDEX(Translations!$D:$ZZ, MATCH(1022,Translations!$A:$A,0), MATCH('Project Information'!$C$4,Translations!$D$1:$ZZ$1,0))
A3: =INDEX(Translations!$D:$ZZ, MATCH(15,Translations!$A:$A,0), MATCH('Project Information'!$C$4,Translations!$D$1:$ZZ$1,0))
A4: =INDEX(Translations!$D:$ZZ, MATCH(4,Translations!$A:$A,0), MATCH('Project Information'!$C$4,Translations!$D$1:$ZZ$1,0))
A5: =INDEX(Translations!$D:$ZZ, MATCH(5,Translations!$A:$A,0), MATCH('Project Information'!$C$4,Translations!$D$1:$ZZ$1,0)) | B5: =INDEX(Translations!$D:$ZZ, MATCH(6,Translations!$A:$A,0), MATCH('Project Information'!$C$4,Translations!$D$1:$ZZ$1,0))
A6: =INDEX(Translations!$D:$ZZ, MATCH(7,Translations!$A:$A,0), MATCH('Project Information'!$C$4,Translations!$D$1:$ZZ$1,0)) | B6: =INDEX(Translations!$D:$ZZ, MATCH(8,Translations!$A:$A,0), MATCH('Project Information'!$C$4,Translations!$D$1:$ZZ$1,0))
A7: =INDEX(Translations!$D:$ZZ, MATCH(9,Translations!$A:$A,0), MATCH('Project Information'!$C$4,Translations!$D$1:$ZZ$1,0)) | B7: =INDEX(Translations!$D:$ZZ, MATCH(10,Translations!$A:$A,0), MATCH('Project Information'!$C$4,Translations!$D$1:$ZZ$1,0))
A8: =INDEX(Translations!$D:$ZZ, MATCH(11,Translations!$A:$A,0), MATCH('Project Information'!$C$4,Translations!$D$1:$ZZ$1,0)) | B8: =INDEX(Translations!$D:$ZZ, MATCH(12,Translations!$A:$A,0), MATCH('Project Information'!$C$4,Translations!$D$1:$ZZ$1,0))
A9: =INDEX(Translations!$D:$ZZ, MATCH(13,Translations!$A:$A,0), MATCH('Project Information'!$C$4,Translations!$D$1:$ZZ$1,0)) | B9: =SUM($H$14:$H$36) | J9: =IF($B$9<=40,"S",IF($B$9<=70,"M",IF($B$9<=100,"L","XL")))
A10: =INDEX(Translations!$D:$ZZ, MATCH(14,Translations!$A:$A,0), MATCH('Project Information'!$C$4,Translations!$D$1:$ZZ$1,0)) | B10: =IF($J$9="S",INDEX(Translations!$D:$ZZ,MATCH(5,Translations!$A:$A,0),MATCH('Project Information'!$C$4,Translations!$D$1:$ZZ$1,0)),IF($J$9="M",INDEX(Translations!$D:$ZZ,MATCH(7,Translations!$A:$A,0),MATCH('Project Information'!$C$4,Translations!$D$1:$ZZ$1,0)),IF($J$9="L",INDEX(Translations!$D:$ZZ,MATCH(9,Translations!$A:$A,0),MATCH('Project Information'!$C$4,Translations!$D$1:$ZZ$1,0)),INDEX(Translations!$D:$ZZ,MATCH(11,Translations!$A:$A,0),MATCH('Project Information'!$C$4,Translations!$D$1:$ZZ$1,0)))))
A11: =INDEX(Translations!$D:$ZZ, MATCH(15,Translations!$A:$A,0), MATCH('Project Information'!$C$4,Translations!$D$1:$ZZ$1,0))
A12: =INDEX(Translations!$D:$ZZ, MATCH(16,Translations!$A:$A,0), MATCH('Project Information'!$C$4,Translations!$D$1:$ZZ$1,0)) | B12: =INDEX(Translations!$D:$ZZ, MATCH(17,Translations!$A:$A,0), MATCH('Project Information'!$C$4,Translations!$D$1:$ZZ$1,0)) | C12: =INDEX(Translations!$D:$ZZ, MATCH(18,Translations!$A:$A,0), MATCH('Project Information'!$C$4,Translations!$D$1:$ZZ$1,0)) | D12: =INDEX(Translations!$D:$ZZ, MATCH(19,Translations!$A:$A,0), MATCH('Project Information'!$C$4,Translations!$D$1:$ZZ$1,0)) | E12: =INDEX(Translations!$D:$ZZ, MATCH(20,Translations!$A:$A,0), MATCH('Project Information'!$C$4,Translations!$D$1:$ZZ$1,0)) | F12: =INDEX(Translations!$D:$ZZ, MATCH(21,Translations!$A:$A,0), MATCH('Project Information'!$C$4,Translations!$D$1:$ZZ$1,0)) | G12: =INDEX(Translations!$D:$ZZ, MATCH(22,Translations!$A:$A,0), MATCH('Project Information'!$C$4,Translations!$D$1:$ZZ$1,0)) | H12: =INDEX(Translations!$D:$ZZ, MATCH(23,Translations!$A:$A,0), MATCH('Project Information'!$C$4,Translations!$D$1:$ZZ$1,0)) | I12: =INDEX(Translations!$D:$ZZ, MATCH(24,Translations!$A:$A,0), MATCH('Project Information'!$C$4,Translations!$D$1:$ZZ$1,0)) | K12: Applicable?
A13: 1 | B13: =INDEX(Translations!$D:$ZZ, MATCH(169,Translations!$A:$A,0), MATCH('Project Information'!$C$4,Translations!$D$1:$ZZ$1,0)) | C13: =INDEX(Translations!$D:$ZZ, MATCH(170,Translations!$A:$A,0), MATCH('Project Information'!$C$4,Translations!$D$1:$ZZ$1,0)) | D13: =INDEX(Translations!$D:$ZZ, MATCH(172,Translations!$A:$A,0), MATCH('Project Information'!$C$4,Translations!$D$1:$ZZ$1,0)) | H13: =IF(OR(TRIM(F13)="Evet",TRIM(F13)="Yes"),E13,IF(G13="","",E13*G13)) | K13: =IFERROR(AND(OR(INDEX('Question Restrictions'!$D:$D,MATCH($B13,'Question Restrictions'!$C:$C,0))="All",ISNUMBER(SEARCH('Project Information'!$C$10,INDEX('Question Restrictions'!$D:$D,MATCH($B13,'Question Restrictions'!$C:$C,0))))),OR(INDEX('Question Restrictions'!$E:$E,MATCH($B13,'Question Restrictions'!$C:$C,0))="All",ISNUMBER(SEARCH('Project Information'!$C$11,INDEX('Question Restrictions'!$E:$E,MATCH($B13,'Question Restrictions'!$C:$C,0))))),OR(INDEX('Question Restrictions'!$F:$F,MATCH($B13,'Question Restrictions'!$C:$C,0))="All",ISNUMBER(SEARCH('Project Information'!$C$12,INDEX('Question Restrictions'!$F:$F,MATCH($B13,'Question Restrictions'!$C:$C,0))))),INDEX('Question Restrictions'!$G:$G,MATCH($B13,'Question Restrictions'!$C:$C,0))="Yes"),TRUE())
A14: 2 | B14: =INDEX(Translations!$D:$ZZ, MATCH(173,Translations!$A:$A,0), MATCH('Project Information'!$C$4,Translations!$D$1:$ZZ$1,0)) | C14: =INDEX(Translations!$D:$ZZ, MATCH(174,Translations!$A:$A,0), MATCH('Project Information'!$C$4,Translations!$D$1:$ZZ$1,0)) | D14: =INDEX(Translations!$D:$ZZ, MATCH(172,Translations!$A:$A,0), MATCH('Project Information'!$C$4,Translations!$D$1:$ZZ$1,0)) | H14: =IF(OR(TRIM(F14)="Evet",TRIM(F14)="Yes"),E14,IF(G14="","",E14*G14)) | K14: =IFERROR(AND(OR(INDEX('Question Restrictions'!$D:$D,MATCH($B14,'Question Restrictions'!$C:$C,0))="All",ISNUMBER(SEARCH('Project Information'!$C$10,INDEX('Question Restrictions'!$D:$D,MATCH($B14,'Question Restrictions'!$C:$C,0))))),OR(INDEX('Question Restrictions'!$E:$E,MATCH($B14,'Question Restrictions'!$C:$C,0))="All",ISNUMBER(SEARCH('Project Information'!$C$11,INDEX('Question Restrictions'!$E:$E,MATCH($B14,'Question Restrictions'!$C:$C,0))))),OR(INDEX('Question Restrictions'!$F:$F,MATCH($B14,'Question Restrictions'!$C:$C,0))="All",ISNUMBER(SEARCH('Project Information'!$C$12,INDEX('Question Restrictions'!$F:$F,MATCH($B14,'Question Restrictions'!$C:$C,0))))),INDEX('Question Restrictions'!$G:$G,MATCH($B14,'Question Restrictions'!$C:$C,0))="Yes"),TRUE())
A15: 3 | B15: =INDEX(Translations!$D:$ZZ, MATCH(175,Translations!$A:$A,0), MATCH('Project Information'!$C$4,Translations!$D$1:$ZZ$1,0)) | C15: =INDEX(Translations!$D:$ZZ, MATCH(176,Translations!$A:$A,0), MATCH('Project Information'!$C$4,Translations!$D$1:$ZZ$1,0)) | D15: =INDEX(Translations!$D:$ZZ, MATCH(172,Translations!$A:$A,0), MATCH('Project Information'!$C$4,Translations!$D$1:$ZZ$1,0)) | H15: =IF(OR(TRIM(F15)="Evet",TRIM(F15)="Yes"),E15,IF(G15="","",E15*G15)) | K15: =IFERROR(AND(OR(INDEX('Question Restrictions'!$D:$D,MATCH($B15,'Question Restrictions'!$C:$C,0))="All",ISNUMBER(SEARCH('Project Information'!$C$10,INDEX('Question Restrictions'!$D:$D,MATCH($B15,'Question Restrictions'!$C:$C,0))))),OR(INDEX('Question Restrictions'!$E:$E,MATCH($B15,'Question Restrictions'!$C:$C,0))="All",ISNUMBER(SEARCH('Project Information'!$C$11,INDEX('Question Restrictions'!$E:$E,MATCH($B15,'Question Restrictions'!$C:$C,0))))),OR(INDEX('Question Restrictions'!$F:$F,MATCH($B15,'Question Restrictions'!$C:$C,0))="All",ISNUMBER(SEARCH('Project Information'!$C$12,INDEX('Question Restrictions'!$F:$F,MATCH($B15,'Question Restrictions'!$C:$C,0))))),INDEX('Question Restrictions'!$G:$G,MATCH($B15,'Question Restrictions'!$C:$C,0))="Yes"),TRUE())
A16: 4 | B16: =INDEX(Translations!$D:$ZZ, MATCH(201,Translations!$A:$A,0), MATCH('Project Information'!$C$4,Translations!$D$1:$ZZ$1,0)) | C16: =INDEX(Translations!$D:$ZZ, MATCH(202,Translations!$A:$A,0), MATCH('Project Information'!$C$4,Translations!$D$1:$ZZ$1,0)) | D16: =INDEX(Translations!$D:$ZZ, MATCH(27,Translations!$A:$A,0), MATCH('Project Information'!$C$4,Translations!$D$1:$ZZ$1,0)) | H16: =IF(OR(TRIM(F16)="Evet",TRIM(F16)="Yes"),E16,IF(G16="","",E16*G16)) | K16: =IFERROR(AND(OR(INDEX('Question Restrictions'!$D:$D,MATCH($B16,'Question Restrictions'!$C:$C,0))="All",ISNUMBER(SEARCH('Project Information'!$C$10,INDEX('Question Restrictions'!$D:$D,MATCH($B16,'Question Restrictions'!$C:$C,0))))),OR(INDEX('Question Restrictions'!$E:$E,MATCH($B16,'Question Restrictions'!$C:$C,0))="All",ISNUMBER(SEARCH('Project Information'!$C$11,INDEX('Question Restrictions'!$E:$E,MATCH($B16,'Question Restrictions'!$C:$C,0))))),OR(INDEX('Question Restrictions'!$F:$F,MATCH($B16,'Question Restrictions'!$C:$C,0))="All",ISNUMBER(SEARCH('Project Information'!$C$12,INDEX('Question Restrictions'!$F:$F,MATCH($B16,'Question Restrictions'!$C:$C,0))))),INDEX('Question Restrictions'!$G:$G,MATCH($B16,'Question Restrictions'!$C:$C,0))="Yes"),TRUE())
A17: 5 | B17: =INDEX(Translations!$D:$ZZ, MATCH(205,Translations!$A:$A,0), MATCH('Project Information'!$C$4,Translations!$D$1:$ZZ$1,0)) | C17: =INDEX(Translations!$D:$ZZ, MATCH(206,Translations!$A:$A,0), MATCH('Project Information'!$C$4,Translations!$D$1:$ZZ$1,0)) | D17: =INDEX(Translations!$D:$ZZ, MATCH(27,Translations!$A:$A,0), MATCH('Project Information'!$C$4,Translations!$D$1:$ZZ$1,0)) | H17: =IF(OR(TRIM(F17)="Evet",TRIM(F17)="Yes"),E17,IF(G17="","",E17*G17)) | K17: =IFERROR(AND(OR(INDEX('Question Restrictions'!$D:$D,MATCH($B17,'Question Restrictions'!$C:$C,0))="All",ISNUMBER(SEARCH('Project Information'!$C$10,INDEX('Question Restrictions'!$D:$D,MATCH($B17,'Question Restrictions'!$C:$C,0))))),OR(INDEX('Question Restrictions'!$E:$E,MATCH($B17,'Question Restrictions'!$C:$C,0))="All",ISNUMBER(SEARCH('Project Information'!$C$11,INDEX('Question Restrictions'!$E:$E,MATCH($B17,'Question Restrictions'!$C:$C,0))))),OR(INDEX('Question Restrictions'!$F:$F,MATCH($B17,'Question Restrictions'!$C:$C,0))="All",ISNUMBER(SEARCH('Project Information'!$C$12,INDEX('Question Restrictions'!$F:$F,MATCH($B17,'Question Restrictions'!$C:$C,0))))),INDEX('Question Restrictions'!$G:$G,MATCH($B17,'Question Restrictions'!$C:$C,0))="Yes"),TRUE())
A18: 6 | B18: =INDEX(Translations!$D:$ZZ, MATCH(209,Translations!$A:$A,0), MATCH('Project Information'!$C$4,Translations!$D$1:$ZZ$1,0)) | C18: =INDEX(Translations!$D:$ZZ, MATCH(210,Translations!$A:$A,0), MATCH('Project Information'!$C$4,Translations!$D$1:$ZZ$1,0)) | D18: =INDEX(Translations!$D:$ZZ, MATCH(172,Translations!$A:$A,0), MATCH('Project Information'!$C$4,Translations!$D$1:$ZZ$1,0)) | H18: =IF(OR(TRIM(F18)="Evet",TRIM(F18)="Yes"),E18,IF(G18="","",E18*G18)) | K18: =IFERROR(AND(OR(INDEX('Question Restrictions'!$D:$D,MATCH($B18,'Question Restrictions'!$C:$C,0))="All",ISNUMBER(SEARCH('Project Information'!$C$10,INDEX('Question Restrictions'!$D:$D,MATCH($B18,'Question Restrictions'!$C:$C,0))))),OR(INDEX('Question Restrictions'!$E:$E,MATCH($B18,'Question Restrictions'!$C:$C,0))="All",ISNUMBER(SEARCH('Project Information'!$C$11,INDEX('Question Restrictions'!$E:$E,MATCH($B18,'Question Restrictions'!$C:$C,0))))),OR(INDEX('Question Restrictions'!$F:$F,MATCH($B18,'Question Restrictions'!$C:$C,0))="All",ISNUMBER(SEARCH('Project Information'!$C$12,INDEX('Question Restrictions'!$F:$F,MATCH($B18,'Question Restrictions'!$C:$C,0))))),INDEX('Question Restrictions'!$G:$G,MATCH($B18,'Question Restrictions'!$C:$C,0))="Yes"),TRUE())
A19: 7 | B19: =INDEX(Translations!$D:$ZZ, MATCH(211,Translations!$A:$A,0), MATCH('Project Information'!$C$4,Translations!$D$1:$ZZ$1,0)) | C19: =INDEX(Translations!$D:$ZZ, MATCH(212,Translations!$A:$A,0), MATCH('Project Information'!$C$4,Translations!$D$1:$ZZ$1,0)) | D19: =INDEX(Translations!$D:$ZZ, MATCH(172,Translations!$A:$A,0), MATCH('Project Information'!$C$4,Translations!$D$1:$ZZ$1,0)) | H19: =IF(OR(TRIM(F19)="Evet",TRIM(F19)="Yes"),E19,IF(G19="","",E19*G19)) | K19: =IFERROR(AND(OR(INDEX('Question Restrictions'!$D:$D,MATCH($B19,'Question Restrictions'!$C:$C,0))="All",ISNUMBER(SEARCH('Project Information'!$C$10,INDEX('Question Restrictions'!$D:$D,MATCH($B19,'Question Restrictions'!$C:$C,0))))),OR(INDEX('Question Restrictions'!$E:$E,MATCH($B19,'Question Restrictions'!$C:$C,0))="All",ISNUMBER(SEARCH('Project Information'!$C$11,INDEX('Question Restrictions'!$E:$E,MATCH($B19,'Question Restrictions'!$C:$C,0))))),OR(INDEX('Question Restrictions'!$F:$F,MATCH($B19,'Question Restrictions'!$C:$C,0))="All",ISNUMBER(SEARCH('Project Information'!$C$12,INDEX('Question Restrictions'!$F:$F,MATCH($B19,'Question Restrictions'!$C:$C,0))))),INDEX('Question Restrictions'!$G:$G,MATCH($B19,'Question Restrictions'!$C:$C,0))="Yes"),TRUE())
A20: 8 | B20: =INDEX(Translations!$D:$ZZ, MATCH(213,Translations!$A:$A,0), MATCH('Project Information'!$C$4,Translations!$D$1:$ZZ$1,0)) | C20: =INDEX(Translations!$D:$ZZ, MATCH(214,Translations!$A:$A,0), MATCH('Project Information'!$C$4,Translations!$D$1:$ZZ$1,0)) | D20: =INDEX(Translations!$D:$ZZ, MATCH(172,Translations!$A:$A,0), MATCH('Project Information'!$C$4,Translations!$D$1:$ZZ$1,0)) | H20: =IF(OR(TRIM(F20)="Evet",TRIM(F20)="Yes"),E20,IF(G20="","",E20*G20)) | K20: =IFERROR(AND(OR(INDEX('Question Restrictions'!$D:$D,MATCH($B20,'Question Restrictions'!$C:$C,0))="All",ISNUMBER(SEARCH('Project Information'!$C$10,INDEX('Question Restrictions'!$D:$D,MATCH($B20,'Question Restrictions'!$C:$C,0))))),OR(INDEX('Question Restrictions'!$E:$E,MATCH($B20,'Question Restrictions'!$C:$C,0))="All",ISNUMBER(SEARCH('Project Information'!$C$11,INDEX('Question Restrictions'!$E:$E,MATCH($B20,'Question Restrictions'!$C:$C,0))))),OR(INDEX('Question Restrictions'!$F:$F,MATCH($B20,'Question Restrictions'!$C:$C,0))="All",ISNUMBER(SEARCH('Project Information'!$C$12,INDEX('Question Restrictions'!$F:$F,MATCH($B20,'Question Restrictions'!$C:$C,0))))),INDEX('Question Restrictions'!$G:$G,MATCH($B20,'Question Restrictions'!$C:$C,0))="Yes"),TRUE())
A21: 9 | B21: =INDEX(Translations!$D:$ZZ, MATCH(215,Translations!$A:$A,0), MATCH('Project Information'!$C$4,Translations!$D$1:$ZZ$1,0)) | C21: =INDEX(Translations!$D:$ZZ, MATCH(216,Translations!$A:$A,0), MATCH('Project Information'!$C$4,Translations!$D$1:$ZZ$1,0)) | D21: =INDEX(Translations!$D:$ZZ, MATCH(172,Translations!$A:$A,0), MATCH('Project Information'!$C$4,Translations!$D$1:$ZZ$1,0)) | H21: =IF(OR(TRIM(F21)="Evet",TRIM(F21)="Yes"),E21,IF(G21="","",E21*G21)) | K21: =IFERROR(AND(OR(INDEX('Question Restrictions'!$D:$D,MATCH($B21,'Question Restrictions'!$C:$C,0))="All",ISNUMBER(SEARCH('Project Information'!$C$10,INDEX('Question Restrictions'!$D:$D,MATCH($B21,'Question Restrictions'!$C:$C,0))))),OR(INDEX('Question Restrictions'!$E:$E,MATCH($B21,'Question Restrictions'!$C:$C,0))="All",ISNUMBER(SEARCH('Project Information'!$C$11,INDEX('Question Restrictions'!$E:$E,MATCH($B21,'Question Restrictions'!$C:$C,0))))),OR(INDEX('Question Restrictions'!$F:$F,MATCH($B21,'Question Restrictions'!$C:$C,0))="All",ISNUMBER(SEARCH('Project Information'!$C$12,INDEX('Question Restrictions'!$F:$F,MATCH($B21,'Question Restrictions'!$C:$C,0))))),INDEX('Question Restrictions'!$G:$G,MATCH($B21,'Question Restrictions'!$C:$C,0))="Yes"),TRUE())
A22: 10 | B22: =INDEX(Translations!$D:$ZZ, MATCH(224,Translations!$A:$A,0), MATCH('Project Information'!$C$4,Translations!$D$1:$ZZ$1,0)) | C22: =INDEX(Translations!$D:$ZZ, MATCH(194,Translations!$A:$A,0), MATCH('Project Information'!$C$4,Translations!$D$1:$ZZ$1,0)) | D22: =INDEX(Translations!$D:$ZZ, MATCH(27,Translations!$A:$A,0), MATCH('Project Information'!$C$4,Translations!$D$1:$ZZ$1,0)) | H22: =IF(OR(TRIM(F22)="Evet",TRIM(F22)="Yes"),E22,IF(G22="","",E22*G22)) | K22: =IFERROR(AND(OR(INDEX('Question Restrictions'!$D:$D,MATCH($B22,'Question Restrictions'!$C:$C,0))="All",ISNUMBER(SEARCH('Project Information'!$C$10,INDEX('Question Restrictions'!$D:$D,MATCH($B22,'Question Restrictions'!$C:$C,0))))),OR(INDEX('Question Restrictions'!$E:$E,MATCH($B22,'Question Restrictions'!$C:$C,0))="All",ISNUMBER(SEARCH('Project Information'!$C$11,INDEX('Question Restrictions'!$E:$E,MATCH($B22,'Question Restrictions'!$C:$C,0))))),OR(INDEX('Question Restrictions'!$F:$F,MATCH($B22,'Question Restrictions'!$C:$C,0))="All",ISNUMBER(SEARCH('Project Information'!$C$12,INDEX('Question Restrictions'!$F:$F,MATCH($B22,'Question Restrictions'!$C:$C,0))))),INDEX('Question Restrictions'!$G:$G,MATCH($B22,'Question Restrictions'!$C:$C,0))="Yes"),TRUE())
A23: 11 | B23: =INDEX(Translations!$D:$ZZ, MATCH(225,Translations!$A:$A,0), MATCH('Project Information'!$C$4,Translations!$D$1:$ZZ$1,0)) | C23: =INDEX(Translations!$D:$ZZ, MATCH(226,Translations!$A:$A,0), MATCH('Project Information'!$C$4,Translations!$D$1:$ZZ$1,0)) | D23: =INDEX(Translations!$D:$ZZ, MATCH(172,Translations!$A:$A,0), MATCH('Project Information'!$C$4,Translations!$D$1:$ZZ$1,0)) | H23: =IF(OR(TRIM(F23)="Evet",TRIM(F23)="Yes"),E23,IF(G23="","",E23*G23)) | K23: =IFERROR(AND(OR(INDEX('Question Restrictions'!$D:$D,MATCH($B23,'Question Restrictions'!$C:$C,0))="All",ISNUMBER(SEARCH('Project Information'!$C$10,INDEX('Question Restrictions'!$D:$D,MATCH($B23,'Question Restrictions'!$C:$C,0))))),OR(INDEX('Question Restrictions'!$E:$E,MATCH($B23,'Question Restrictions'!$C:$C,0))="All",ISNUMBER(SEARCH('Project Information'!$C$11,INDEX('Question Restrictions'!$E:$E,MATCH($B23,'Question Restrictions'!$C:$C,0))))),OR(INDEX('Question Restrictions'!$F:$F,MATCH($B23,'Question Restrictions'!$C:$C,0))="All",ISNUMBER(SEARCH('Project Information'!$C$12,INDEX('Question Restrictions'!$F:$F,MATCH($B23,'Question Restrictions'!$C:$C,0))))),INDEX('Question Restrictions'!$G:$G,MATCH($B23,'Question Restrictions'!$C:$C,0))="Yes"),TRUE())
